Workbook

Sheet サマリー
B1: 西友MD基幹統合（Project West）外部IF開発 見積書
B2: 対象工程：詳細設計・開発・単体テスト ／ 対象課題：BO系・自動補充Sinops系
B3: 作成日：2026/08/31 ／ 単位：工数=人日、金額=円
B5: ■ 単価前提（入力欄）
B6: 工程 | C6: 単価（円/人日） | D6: 備考
B7: PJ管理 | C7: 40000 | D7: PM、横断課題解決単価
B8: 詳細設計 | C8: 27500 | D8: 詳細設計工程単価
B9: 開発 | C9: 27500 | D9: 製造工程単価
B10: 単体テスト | C10: 27500 | D10: 製造工程単価
B12: ■ 課題別サマリー（直接工数ベース）
B13: 課題 | C13: 詳細設計 (人日) | D13: 開発 (人日) | E13: 単体テスト (人日) | F13: 工数計 (人日) | G13: 詳細設計 (円) | H13: 開発 (円) | I13: 単体テスト (円) | J13: 金額計（円）
B14: BO系 | C14: ='BO系明細'!E22 -> 17 | D14: ='BO系明細'!F22 -> 23.5 | E14: ='BO系明細'!G22 -> 13 | F14: =SUM(C14:E14) -> 53.5 | G14: =C14*$C$8 -> 467500 | H14: =D14*$C$9 -> 646250 | I14: =E14*$C$10 -> 357500 | J14: =SUM(G14:I14) -> 1471250
B15: 自動補充Sinops系 | C15: ='Sinops系明細'!E78 -> 136 | D15: ='Sinops系明細'!F78 -> 144 | E15: ='Sinops系明細'!G78 -> 123 | F15: =SUM(C15:E15) -> 403 | G15: =C15*$C$8 -> 3740000 | H15: =D15*$C$9 -> 3960000 | I15: =E15*$C$10 -> 3382500 | J15: =SUM(G15:I15) -> 11082500
B16: 共通基盤（両課題共用） | C16: ='共通・PJ管理'!E9 -> 10 | D16: ='共通・PJ管理'!F9 -> 30 | E16: ='共通・PJ管理'!G9 -> 3 | F16: =SUM(C16:E16) -> 43 | G16: =C16*$C$8 -> 275000 | H16: =D16*$C$9 -> 825000 | I16: =E16*$C$10 -> 82500 | J16: =SUM(G16:I16) -> 1182500
B17: 小計（開発スコープ） | C17: =SUM(C14:C16) -> 163 | D17: =SUM(D14:D16) -> 197.5 | E17: =SUM(E14:E16) -> 139 | F17: =SUM(C17:E17) -> 499.5 | G17: =C17*$C$8 -> 4482500 | H17: =D17*$C$9 -> 5431250 | I17: =E17*$C$10 -> 3822500 | J17: =SUM(G17:I17) -> 13736250
B18: PJ管理 | C18: ='共通・PJ管理'!E14 -> 50 | D18: ='共通・PJ管理'!F14 -> 0 | E18: ='共通・PJ管理'!G14 -> 0 | F18: =SUM(C18:E18) -> 50 | G18: =C18*$C$7 -> 2000000 | H18: =D18*$C$9 -> 0 | I18: =E18*$C$10 -> 0 | J18: =SUM(G18:I18) -> 2000000
B19: 合計 | C19: =C17+C18 -> 213 | D19: =D17+D18 -> 197.5 | E19: =E17+E18 -> 139 | F19: =SUM(C19:E19) -> 549.5 | G19: =G17+G18 -> 6482500 | H19: =H17+H18 -> 5431250 | I19: =I17+I18 -> 3822500 | J19: =SUM(G19:I19) -> 15736250
B21: ■ レイヤー別内訳（人日）
B22: レイヤー | C22: 範囲 | D22: BO系 | E22: 自動補充Sinops系 | F22: 合計 | G22: 前提条件
B23: Layer① | C23: TRIAL↔GCS | D23: ='BO系明細'!H8 -> 34 | E23: ='Sinops系明細'!H32 -> 297 | F23: =SUM(D23:E23) -> 331 | G23: IF用サーバー構築、MD/SCM・BOの共通化、型変換
B24: Layer② | C24: GCS→DWH | D24: ='BO系明細'!H14 -> 9 | E24: ='Sinops系明細'!H47 -> 31 | F24: =SUM(D24:E24) -> 40 | G24: 基本はGCS上のファイルをそのままIntakeテーブルに格納
B25: Layer③ | C25: DWH・GCS↔業務システム | D25: ='BO系明細'!H20 -> 10.5 | E25: ='Sinops系明細'!H76 -> 75 | F25: =SUM(D25:E25) -> 85.5 | G25: 業務システムの個別対応
B26: 共通基盤 | C26: Layer①/②共通 | D26: － | E26: － | F26: ='共通・PJ管理'!H9 -> 43 | G26: IF用サーバー立ち上げ、DataSpider設定・教育
B27: PJ管理 | C27: 横断 | D27: － | E27: － | F27: ='共通・PJ管理'!H14 -> 50 | G27: 進捗・品質管理、横断課題対応、MT対応など
B28: 合計 | D28: =SUM(D23:D27) -> 53.5 | E28: =SUM(E23:E27) -> 403 | F28: =SUM(F23:F27) -> 549.5

Sheet BO系明細
B1: 【BO系】外部IF 工数明細（詳細設計・開発・単体テスト）
B2: 単位：人日 ／ 出典：西友MD基幹統合 外部IF工数見積（Googleスプレッドシート）
B4: ■ Layer① TRIAL↔GCS（外部IFプログラム開発） | I4: IF用サーバー構築、MD/SCM・BOの共通化、型変換
B5: IF名称／マスタ種別 | C5: 対応IF No. | D5: 項目数 | E5: 詳細設計 | F5: 開発 | G5: 単体テスト | H5: 小計 | I5: 備考
B6: 商品マスタ(基本) | C6: BO-15/32/33 | D6: 126 | E6: 6 | F6: 8 | G6: 4 | H6: =SUM(E6:G6) -> 18 | I6: 今から着手可能な割合50%、残りはマスタ統合PJでの確定後 | J6: 〇
B7: 商品マスタ(店別) | C7: BO-34 | D7: 83 | E7: 5 | F7: 7 | G7: 4 | H7: =SUM(E7:G7) -> 16 | I7: 今から着手可能な割合60%、残りはマスタ統合PJでの確定後 | J7: 〇
B8: 小計 | E8: =SUM(E6:E7) -> 11 | F8: =SUM(F6:F7) -> 15 | G8: =SUM(G6:G7) -> 8 | H8: =SUM(H6:H7) -> 34
B10: ■ Layer② GCS→DWH（DataSpider 取込ジョブ開発） | I10: 基本はGCS上のファイルをそのままIntakeテーブルに格納
B11: IF名称／マスタ種別 | C11: 対応IF No. | D11: 項目数 | E11: 詳細設計 | F11: 開発 | G11: 単体テスト | H11: 小計 | I11: 備考
B12: 商品マスタ(基本) | C12: BO-15/32/33 | D12: 126 | E12: 1.5 | F12: 2 | G12: 1 | H12: =SUM(E12:G12) -> 4.5 | J12: 〇
B13: 商品マスタ(店別) | C13: BO-34 | D13: 83 | E13: 1.5 | F13: 2 | G13: 1 | H13: =SUM(E13:G13) -> 4.5 | J13: 〇
B14: 小計 | E14: =SUM(E12:E13) -> 3 | F14: =SUM(F12:F13) -> 4 | G14: =SUM(G12:G13) -> 2 | H14: =SUM(H12:H13) -> 9
B16: ■ Layer③ DWH・GCS→BO（DataSpider 連携ジョブ開発） | I16: 業務システムの個別対応
B17: IF名称／マスタ種別 | C17: 対応IF No. | D17: 項目数 | E17: 詳細設計 | F17: 開発 | G17: 単体テスト | H17: 小計 | I17: 備考
B18: 国内流通向け商品マスタ連携(基本) | C18: BO-33 | D18: 126 | E18: 1.5 | F18: 2.5 | G18: 1.5 | H18: =SUM(E18:G18) -> 5.5 | J18: 〇
B19: 国内流通向け商品マスタ連携(店別) | C19: BO-34 | D19: 83 | E19: 1.5 | F19: 2 | G19: 1.5 | H19: =SUM(E19:G19) -> 5 | J19: 〇
B20: 小計 | E20: =SUM(E18:E19) -> 3 | F20: =SUM(F18:F19) -> 4.5 | G20: =SUM(G18:G19) -> 3 | H20: =SUM(H18:H19) -> 10.5
B22: 合計（当課題） | E22: =E8+E14+E20 -> 17 | F22: =F8+F14+F20 -> 23.5 | G22: =G8+G14+G20 -> 13 | H22: =H8+H14+H20 -> 53.5
B24: ※ 青字セルが工数入力値です。変更するとサマリーの金額まで自動再計算されます。

Sheet Sinops系明細
B1: 【自動補充Sinops系】外部IF 工数明細（詳細設計・開発・単体テスト）
B2: 単位：人日 ／ 出典：西友MD基幹統合 外部IF工数見積（Googleスプレッドシート）
B4: ■ Layer① TRIAL↔GCS（外部IFプログラム開発） | I4: IF用サーバー構築、MD/SCM・BOの共通化、型変換
B5: IF名称／マスタ種別 | C5: 対応IF No. | D5: 項目数 | E5: 詳細設計 | F5: 開発 | G5: 単体テスト | H5: 小計 | I5: 備考
B6: 商品マスタ | C6: Sinops-01 | D6: 16 | E6: 5 | F6: 5 | G6: 3 | H6: =SUM(E6:G6) -> 13 | I6: 各種マスター課題の解決は前提、進捗次第詳細設計着手する
B7: 店舗商品マスタ | C7: Sinops-02 | D7: 13 | E7: 5 | F7: 5 | G7: 3 | H7: =SUM(E7:G7) -> 13 | I7: 各種マスター課題の解決は前提、進捗次第詳細設計着手する
B8: カテゴリマスタ | C8: Sinops-03 | D8: 4 | E8: 2 | F8: 2 | G8: 2 | H8: =SUM(E8:G8) -> 6 | I8: 各種マスター課題の解決は前提、進捗次第詳細設計着手する
B9: 仕入先マスタ | C9: Sinops-04 | D9: 2 | E9: 1 | F9: 1 | G9: 1 | H9: =SUM(E9:G9) -> 3 | I9: 各種マスター課題の解決は前提、進捗次第詳細設計着手する
B10: ケースバラ変換マスタ | C10: Sinops-05 | D10: 6 | E10: 5 | F10: 5 | G10: 4 | H10: =SUM(E10:G10) -> 14 | I10: 各種マスター課題の解決は前提、進捗次第詳細設計着手する
B11: 販売実績 | C11: Sinops-06 | D11: 11 | E11: 4 | F11: 3 | G11: 3 | H11: =SUM(E11:G11) -> 10 | I11: 詳細設計・開発・単体テストは前提依存なし、Phase3の結合テストは売上データ統合が必要
B12: 時間帯別販売数量 | C12: Sinops-07 | D12: 28 | E12: 5 | F12: 5 | G12: 4 | H12: =SUM(E12:G12) -> 14 | I12: 詳細設計・開発・単体テストは前提依存なし、Phase3の結合テストは売上データ統合が必要
B13: 来客数実績 | C13: Sinops-08 | D13: 3 | E13: 1.5 | F13: 1 | G13: 1 | H13: =SUM(E13:G13) -> 3.5 | I13: 詳細設計・開発・単体テストは前提依存なし、Phase3の結合テストは売上データ統合が必要
B14: 廃棄情報 | C14: Sinops-09 | D14: 4 | E14: 1.5 | F14: 2 | G14: 2 | H14: =SUM(E14:G14) -> 5.5 | I14: 詳細設計・開発・単体テストは前提依存なし、Phase3の結合テストは廃棄データ統合が必要
B15: 在庫修正（店舗） | C15: Sinops-10 | D15: 4 | E15: 4 | F15: 3 | G15: 3 | H15: =SUM(E15:G15) -> 10 | I15: 詳細設計・開発・単体テストは前提依存なし、Phase3の結合テストは在庫データ統合が必要
B16: 在庫修正（センター） | C16: Sinops-10 | D16: 4 | E16: 4 | F16: 3 | G16: 3 | H16: =SUM(E16:G16) -> 10 | I16: 詳細設計・開発・単体テストは前提依存なし、Phase3の結合テストはWMSセンター在庫データ統合が必要
B17: 入荷実績 | C17: Sinops-11 | D17: 6 | E17: 4 | F17: 3 | G17: 3 | H17: =SUM(E17:G17) -> 10 | I17: 詳細設計・開発・単体テストは前提依存なし、Phase3の結合テストは入荷実績データ統合が必要(便SHINISE連携)
... B31: 発注勧告(翌日以降分) | C31: Sinops-25 | D31: 17 | E31: 5 | F31: 5 | G31: 4 | H31: =SUM(E31:G31) -> 14 | I31: 詳細設計・開発・単体テストは前提依存なし CORESAVER連携→SHINISE連携？？？
B32: 小計 | E32: =SUM(E6:E31) -> 106 | F32: =SUM(F6:F31) -> 105 | G32: =SUM(G6:G31) -> 86 | H32: =SUM(H6:H31) -> 297
B34: ■ Layer② GCS→DWH（DataSpider 取込ジョブ開発） | I34: 基本はGCS上のファイルをそのままIntakeテーブルに格納
B35: IF名称／マスタ種別 | C35: 対応IF No. | D35: 項目数 | E35: 詳細設計 | F35: 開発 | G35: 単体テスト | H35: 小計 | I35: 備考
B36: 商品マスタ | C36: Sinops-01 | D36: 16 | E36: 1 | F36: 1 | G36: 1 | H36: =SUM(E36:G36) -> 3
B37: 店舗商品マスタ | C37: Sinops-02 | D37: 13 | E37: 1 | F37: 1 | G37: 1 | H37: =SUM(E37:G37) -> 3
B38: カテゴリマスタ | C38: Sinops-03 | D38: 4 | E38: 0.5 | F38: 1 | G38: 1 | H38: =SUM(E38:G38) -> 2.5
B39: 仕入先マスタ | C39: Sinops-04 | D39: 2 | E39: 0.5 | F39: 1 | G39: 1 | H39: =SUM(E39:G39) -> 2.5
B40: ケースバラ変換マスタ | C40: Sinops-05 | D40: 6 | E40: 0.5 | F40: 1 | G40: 1 | H40: =SUM(E40:G40) -> 2.5
B41: 発注スケジュール | C41: Sinops-13 | D41: 9 | E41: 0.5 | F41: 1 | G41: 1 | H41: =SUM(E41:G41) -> 2.5
B42: 棚割明細 | C42: Sinops-14 | D42: 15 | E42: 1 | F42: 1 | G42: 1 | H42: =SUM(E42:G42) -> 3
B43: 商品マスタ【倉庫】 | C43: Sinops-16 | D43: 20 | E43: 1.5 | F43: 1.5 | G43: 1 | H43: =SUM(E43:G43) -> 4
B44: 仕入先マスタ【倉庫】 | C44: Sinops-17 | D44: 2 | E44: 0.5 | F44: 1 | G44: 1 | H44: =SUM(E44:G44) -> 2.5
B45: 仕入先休日設定【倉庫】 | C45: Sinops-18 | D45: 3 | E45: 0.5 | F45: 1 | G45: 1 | H45: =SUM(E45:G45) -> 2.5
B46: 仕入先発注曜日設定【倉庫】 | C46: Sinops-19 | D46: 13 | E46: 1 | F46: 1 | G46: 1 | H46: =SUM(E46:G46) -> 3
B47: 小計 | E47: =SUM(E36:E46) -> 8.5 | F47: =SUM(F36:F46) -> 11.5 | G47: =SUM(G36:G46) -> 11 | H47: =SUM(H36:H46) -> 31
B49: ■ Layer③ DWH・GCS↔Sinops（DataSpider 連携ジョブ開発） | I49: 業務システムの個別対応
B50: IF名称／マスタ種別 | C50: 対応IF No. | D50: 項目数 | E50: 詳細設計 | F50: 開発 | G50: 単体テスト | H50: 小計 | I50: 備考
B51: 商品マスタ | C51: Sinops-01 | D51: 16 | E51: 1 | F51: 1 | G51: 1 | H51: =SUM(E51:G51) -> 3 | I51: マスタ
B52: 店舗商品マスタ | C52: Sinops-02 | D52: 13 | E52: 1 | F52: 1 | G52: 1 | H52: =SUM(E52:G52) -> 3 | I52: マスタ
B53: カテゴリマスタ | C53: Sinops-03 | D53: 4 | E53: 0.5 | F53: 1 | G53: 1 | H53: =SUM(E53:G53) -> 2.5 | I53: マスタ
B54: 仕入先マスタ | C54: Sinops-04 | D54: 2 | E54: 0.5 | F54: 1 | G54: 1 | H54: =SUM(E54:G54) -> 2.5 | I54: マスタ
B55: ケースバラ変換マスタ | C55: Sinops-05 | D55: 6 | E55: 0.5 | F55: 1 | G55: 1 | H55: =SUM(E55:G55) -> 2.5 | I55: マスタ
B56: 販売実績 | C56: Sinops-06 | D56: 11 | E56: 1 | F56: 1 | G56: 1 | H56: =SUM(E56:G56) -> 3 | I56: 実績・在庫
...

Sheet 共通・PJ管理
B1: 【共通基盤・PJ管理】工数明細
B2: 単位：人日 ／ 出典：西友MD基幹統合 外部IF工数見積（Googleスプレッドシート）
B4: ■ 共通基盤（両課題で共用） | I4: IF用サーバー／DataSpider の立ち上げ・設定・教育
B5: IF名称／マスタ種別 | C5: 対応IF No. | D5: 項目数 | E5: 詳細設計 | F5: 開発 | G5: 単体テスト | H5: 小計 | I5: 備考
B6: Layer① 共通 | C6: IF用サーバー(DEV、STG、PROD)設計、立ち上げ、設定 | D6: － | E6: 5 | F6: 15 | G6: 0 | H6: =SUM(E6:G6) -> 20 | I6: BO系／Sinops系の双方で使用
B7: Layer① 共通 | C7: Hinemosジョブ設定 | D7: － | E7: 5 | F7: 5 | G7: 3 | H7: =SUM(E7:G7) -> 13 | I7: BO系／Sinops系の双方で使用
B8: Layer② 共通 | C8: DataSpider関連設定、教育 | D8: － | E8: 0 | F8: 10 | G8: 0 | H8: =SUM(E8:G8) -> 10 | I8: BO系／Sinops系の双方で使用
B9: 小計 | E9: =SUM(E6:E8) -> 10 | F9: =SUM(F6:F8) -> 30 | G9: =SUM(G6:G8) -> 3 | H9: =SUM(H6:H8) -> 43
B11: ■ PJ管理 | I11: 進捗・品質管理、横断課題対応、MT対応など
B12: IF名称／マスタ種別 | C12: 対応IF No. | D12: 項目数 | E12: 詳細設計 | F12: 開発 | G12: 単体テスト | H12: 小計 | I12: 備考
B13: PJ管理 | C13: － | D13: － | E13: 50 | F13: 0 | G13: 0 | H13: =SUM(E13:G13) -> 50 | I13: 全課題横断。詳細設計単価で計上
B14: 小計 | E14: =SUM(E13) -> 50 | F14: =SUM(F13) -> 0 | G14: =SUM(G13) -> 0 | H14: =SUM(H13) -> 50
B16: 合計（当課題） | E16: =E9+E14 -> 60 | F16: =F9+F14 -> 30 | G16: =G9+G14 -> 3 | H16: =H9+H14 -> 93
B18: ※ 青字セルが工数入力値です。変更するとサマリーの金額まで自動再計算されます。

Sheet 前提条件・注記BK
B1: 前提条件・注記
B4: ■ 見積範囲
C5: ・本見積は「詳細設計」「開発」「単体テスト」の3工程のみを対象とします。要件定義・基本設計、結合テスト、総合テスト、移行、運用保守は含みません。
C6: ・対象課題は BO系（バックオフィス連携）と 自動補充Sinops系 の2課題です。棚割・WMS・インテージ等の他領域は本見積の対象外です。
C7: ・レイヤー構成：Layer①=TRIAL↔GCS（外部IFプログラム開発）、Layer②=GCS→DWH（DataSpider取込ジョブ）、Layer③=DWH・GCS↔業務システム（DataSpider連携ジョブ）。
B9: ■ 単価・工数
C10: ・単価は PM 40,000円/人日、詳細設計・開発・単体テスト 27,500円/人日（いずれも税抜）。PM以外の出張対応の場合、35,000円/人日になります。
C11: ・PJ管理は進捗・品質管理、横断課題対応、会議体対応を含み、詳細設計単価で計上しています。
C12: ・共通基盤はIF用サーバーの立ち上げ・設定、DataSpider関連設定・教育、Hinemos関連で、両課題で共用のため独立計上しています。配賦後サマリーでは直接工数比で按分しています。
B14: ■ 技術前提
C15: ・Layer②は原則としてGCS上のファイルをそのままIntakeテーブルへ格納する方式を前提としています。変換要件が発生する場合は追加工数となります。
C16: ・BO-01/02/03（GLOVIA向け仕入先マスタ）はDWH連携不要のため、Layer②の工数は0としています。
C17: ・Sinops-11（入荷実績）はWMSデータ連携が完了していることを前提とします。
C18: ・Sinops-13（発注スケジュール）は、発注締め時間マスタがCoresaverから出力されること、自動発注対象マスタがShiniseから連携されることを前提とします。
C19: ・Sinops-14（棚割明細）は棚割データ連携が完了していることを前提とし、受信・送信の双方向を工数に含みます。
C20: ・Sinops-18（仕入先休日設定【倉庫】）はTRIAL自動発注データ連携を前提とします。
C21: ・Sinops-10（在庫修正・センター）は Hitluster→Sinops のルートか要確認であり、確定次第の工数見直しが必要です。
B23: ■ 除外・リスク
C24: ・未確定項目の変更対応分は一定量を織り込んでいますが、想定フローと異なる方式が確定した場合の追加開発分は含んでいません。
C25: ・未確定項目→マスタ統合PJ、本PJと切り分ける
C26: ・IF本数・項目数の増減、および仕様確定の遅延が発生した場合は、工数・スケジュールを再見積します。

Sheet 前提条件・注記
B1: 前提条件・注記
B3: ■ 見積範囲
B4: 1 | C4: ・本見積は「詳細設計」「開発」「単体テスト」の3工程のみを対象とします。要件定義・基本設計、結合テスト、総合テスト、移行、運用保守は含みません。
B5: 2 | C5: ・対象課題は BO系（バックオフィス連携）と 自動補充Sinops系 の2課題です。棚割・WMS・インテージ等の他領域は本見積の対象外です。
B6: 3 | C6: ・レイヤー構成：Layer①=TRIAL↔GCS（外部IFプログラム開発）、Layer②=GCS→DWH（DataSpider取込ジョブ）、Layer③=DWH・GCS↔業務システム（BO系・自動補充Sinops）（DataSpider連携ジョブ）。
B8: ■ 単価・工数
B9: 1 | C9: ・単価は PM 40,000円/人日、詳細設計・開発・単体テスト 27,500円/人日。出張対応の場合、35,000円/人日になります。
B10: 2 | C10: ・PJ管理は進捗・品質管理、横断課題対応、会議体対応を含みます
B11: 3 | C11: ・共通基盤はIF用サーバーの立ち上げ・設定、DataSpider関連設定・教育、Hinemos関連で、両課題で共用のため独立計上しています。
B13: ■ 確定した前提（自動補充システム進捗報告 反映）
B14: No. | C14: 前提項目 | D14: 確定内容 | E14: 見積・計画への影響
B15: 1 | C15: 発注区分の統合ルール | D15: Sinopsでは発注勧告の生成時にこの情報を使用していないため、そのまま連携する | E15: 変換ロジック不要。Sinops-22〜25（発注勧告）の詳細設計を確定扱いとし、追加工数は見込まない
B16: 2 | C16: 棚割データの連携方式 | D16: Store Managerの棚割データを西友のDWHへ格納し、Sinopsへの連携データ生成時に使用する | E16: Sinops-14/15 の連携ルートが確定。詳細設計に着手可能。ただしダミー棚割データ作成・売場コード定義は棚割側の対応待ち
B17: 3 | C17: 仕入先マスタの統合方針 | D17: 現行のまま使用。移行時に統合するが、現行の9桁を移行して使用する予定 | E17: BO系・Sinops系ともに仕入先マスタはコード変換なしを前提。マスタ統合課題側での正式確認が取れ次第、確定扱いとする
B18: 4 | C18: マスタデータの統合 | D18: 統合対象・方式の詳細は、マスタ統合課題の中で対応する | E18: BO系・Sinops系の店舗マスタ・商品マスタはPhase1仕様で見積。マスタ統合方式の確定後に差分見積とする
B20: ■ 残課題 と工数・スケジュールへの影響
B21: No. | C21: 残課題 | D21: 対応方法 | E21: 対応内容 | F21: 工数・スケジュールへの影響
B22: 1 | C22: 便区分の欠落 | D22: Shiniseで対応 | E22: Shiniseで便区分を開発する事で対応 | F22: Sinops-13/22〜25 の前提。Shinise側の開発完了が単体テストの前提条件となる（本見積にはShinise側の開発工数を含まない）
B23: 2 | C23: 営業在庫の24時スナップショット | D23: Shiniseで対応 | E23: Shiniseからのデータ抽出可能 | F23: Sinops-06〜10（実績・在庫）の工数はそのまま有効
B24: 3 | C24: 新商品の在庫連携 | D24: IF作成 | E24: 西友DWH上の棚割のデータとトライアルMD基幹のマスタ情報を参照して、新商品の在庫データ連携I/Fを構築する | F24: Sinops-15 の構築方式が確定。Layer① 20人日・Layer③ 3人日は本方式を前提とした見積
B25: 4 | C25: 自動発注対象マスタ | D25: マスタ統合課題で対応 | E25: 自動発注対象マスタ作成 | F25: Sinops-13 の前提がマスタ統合課題で作成。マスタ作成完了が開発着手の前提となる
B26: 5 | C26: 棚割明細のダミー棚割データ作成、売場コード定義 | D26: 棚割で対応 | E26: データ作成と定義明確 | F26: Sinops-14 の単体テスト実施に必要。棚割側の対応が遅延した場合、単体テスト完了が同幅でスライド
B27: 6 | C27: ケースバラ変換マスタ | D27: 方針決定 | E27: 波多野さんより西友内部でメンテナンスできるか集中討議 | F27: Sinops-05（四つパターン、計19人日）の唯一の未決定事項。運用主体・メンテ方式により工数が変動する可能性があり、方針確定まで詳細設計に着手できない
B28: 7 | C28: 発注スケジュール作成ロジック | D28: 詳細設計で確定 | E28: 発注スケジュール作成のプロセス詳細処理仕様の解析と対応 | F28: 詳細設計内で確定する方針のため事前の方針決定は不要。ただし解析結果が想定と大きく異なる場合はSinops-13 の再見積が必要
B30: ■ 技術前提（IF別）
B31: 1 | C31: ・Layer②は原則としてGCS上のファイルをそのままIntakeテーブルへ格納する方式を前提としています。変換要件が発生する場合は追加工数となります。
B32: 2 | C32: ・BO-01/02/03（GLOVIA向け仕入先マスタ）はDWH連携不要のため、Layer②の工数は0としています。
B33: 3 | C33: ・Sinops-11（入荷実績）はWMSデータ連携が完了していることを前提とします。
B34: 4 | C34: ・Sinops-14（棚割明細）：Store Managerの棚割データを西友DWHへ格納し、Sinopsへの連携データ生成時に使用する方式で確定。受信・送信の双方向を工数に含みます。
B35: 5 | C35: ・Sinops-15（新商品用在庫データ連携）：西友DWH上の棚割データとTRIAL MD基幹のマスタ情報を参照してI/Fを構築する方式で確定。
B36: 6 | C36: ・Sinops-18（仕入先休日設定【倉庫】）はTRIAL自動発注データ連携を前提とします。
B37: 7 | C37: ・Sinops-22〜25（発注勧告）：発注区分はSinopsが発注勧告生成時に使用しないため、変換せずそのまま連携します。便区分はShinise側の開発完了が前提です。
B39: ■ 除外・リスク
B40: 1 | C40: ・マスタ連携の未確定項目は、マスタ統合課題と本PJで切り分けて管理します。
B41: 2 | C41: ・他チーム対応事項（Shiniseの便区分開発／棚割のダミーデータ作成・売場コード定義／マスタ統合課題での自動発注対象マスタ作成）は本見積の工数外です。対応が遅延した場合、該当IFの開発・単体テストが同幅でスライドします。
B42: 3 | C42: ・Shinise側で開発される便区分の仕様が確定していないため、確定内容によってはSinops-13/22〜25 の変換処理に追加工数が発生する可能性があります。
B43: 4 | C43: ・IF本数・項目数の増減、および仕様確定の遅延が発生した場合は、工数・スケジュールを再見積します。
B45: ■ 今後アクション
B46: 1 | C46: ・残課題の追跡（最優先はケースバラ変換マスタの運用・メンテナンス方針の決定）。
B47: 2 | C47: ・詳細設計・開発テストの見積概算の精緻化（確定した前提を織り込み、本見積を更新）。
...
