Workbook
Name _1: #N/A
Name _111: #REF!
Name _2: #REF!
Name _222: #REF!
Name _4901070301881: #REF!
Name _9店ABC自社路線表: #REF!
Name _c: [3]配荷目標!$AH$4
Name \a: [11]ﾌﾟﾚｾﾞﾝ資!$E$5
Name \b: [11]ﾌﾟﾚｾﾞﾝ資!$E$8
Name \c: [11]ﾌﾟﾚｾﾞﾝ資!$E$11:$E$13
Name \d: [11]ﾌﾟﾚｾﾞﾝ資!$E$16
Name \e: [11]ﾌﾟﾚｾﾞﾝ資!$E$19
Name \f: [11]ﾌﾟﾚｾﾞﾝ資!$E$21
Name \p: #REF!
Name ⑧: [48]⑤優先順位表!#REF!
Name ａ: [3]配荷目標!$AV$1
Name a1D114: #REF!
Name aa: [3]配荷目標!$A$1
Name aaa: #REF!
Name aaaa: [47]⑤優先順位表!#REF!
Name aaaaa: #REF!
Name aaaaaaaasssdsdfcc: #REF!
Name ac: [39]万代比数!#REF!
Name ARARI: #REF!
Name aw: #REF!
Name B: #REF!
Name ＢＢ: [37]Sheet1!$E$107
Name ｂｇｂ: #REF!
Name ｂｎ: #REF!
Name COLNUM: #REF!
Name COLSZ: #REF!
Name DATA: #REF!
Name db: [41]SPLDAT!$A$1:$H$1000
Name DD: [39]万代比数!#REF!
Name ｄｄｄ: #REF!
Name dgfhndhndhnhgnhf: [53]イレブン!#REF!
Name dtdrfddgtyret: #REF!
Name dzghjhgdfggdh: [50]コクミン!$C$2:$R$103
Name eretrytryg: #REF!
Name estrdyfuygio: #REF!
Name Extract2: #REF!
Name Extract3: [47]⑤優先順位表!#REF!
Name Extract4: #REF!
Name extractie: #REF!
Name fcghyu: #REF!
Name fff: #REF!
Name fgjhgdhfdhjmghgdfhgg: #REF!
Name fgnfgmngfmfgjdfmgfg: [53]イレブン!#REF!
Name FILEHOZON: [57]!FILEHOZON
Name ｇ: [27]ﾃﾚｺTｼｬﾂ!$AD$343
Name gghvhysdfkuhgiyuiew: #REF!
Name goukei: [27]ﾃﾚｺTｼｬﾂ!#REF!
Name gyhfytfrdrd: #REF!
Name ＨＡ台帳: #REF!
Name ｈｄｓｒ: #REF!
Name hduyhaghyahgfuysa: [53]イレブン!#REF!
Name hfusiygiushyusiuhiys: [53]イレブン!#REF!
Name hgfhygfuysghfsgsgyshgi: #REF!
Name hhkiuhyigtdstgo: #REF!
Name hiuyouoiuhuytrasdfguhkhj: #REF!

Sheet 仕入伝票(purchase_slip)
A1: 項目マッピング表 ― 仕入伝票（MD基幹システム 標準外部IF／WMS→MD基幹 IFSYLMS230R TC総量入荷実績データ）
A2: 判定凡例： ○ 直接マッピング可 △ 変換・加工が必要 ✕ GAPあり（要対応） ― 固定値／NULL／システム内部採番のため対象外 ｜ MD基幹＝統合先（仕入伝票 標準外部IF）、WMS＝統合元（IFSYLMS230R TC総量入荷実績データ）
A3: No. | B3: 必須 | C3: MD基幹 項目名 | D3: MD基幹 型/桁 | E3: FMT内容 | F3: Hitluster 項目名 | G3: Hitluster 型/バイト | H3: 判定 | I3: 変換ルール・留意事項
A4: 1 | B4: ○ | C4: 納品日 | D4: dbDate_t/8 | E4: CONVERT(VARCHAR(12) , DCAM.INSPDATE, 112 ) | F4: 検品倉庫着荷指定日 | G4: 文字列/8 | H4: 〇 | I4: WMSの「検品倉庫着荷指定日（検品TC倉庫作業予定日）」をMD基幹の納品日として使用する想定。
A5: 2 | C5: 伝票ID | D5: int64_t/19 | E5: NULL | F5: ― | G5: ― | H5: ― | I5: 現状TRIAL：NULL
A6: 3 | C6: 伝票履歴先頭ID | D6: int64_t/19 | E6: NULL | F6: ― | G6: ― | H6: ― | I6: 現状TRIAL：NULL
A7: 4 | B7: ○ | C7: 伝票区分 | D7: int16_t/5 | E7: DCAM.SLIPDIVISION | F7: （該当なし） | G7: ― | H7: ✕ | I7: GAPあり：仕入の場合：10 振替の場合：30
A8: 5 | B8: ○ | C8: 伝票番号 | D8: char/10 | E8: DCAM.SLIPNO | F8: 伝票番号（備考：発注伝票番号） | G8: 文字列/10 | H8: ○ | I8: 伝票番号（備考：発注伝票番号）
A9: 6 | B9: ○ | C9: 店舗コード | D9: char/6 | E9: DCAM.DEMANDCD | F9: （該当なし） | G9: ― | H9: △ | I9: 納品センターしかない 出荷実績と繋がって出力するか、要検討。
A10: 7 | C10: 部門コード | D10: char/8 | E10: DCAM.DEPARTMENTCD | F10: 部門コード | G10: 文字列/2 | H10: △ | I10: カテゴリマスタ統合に関わります
A11: 8 | B11: ○ | C11: 仕入先コード | D11: char/8 | E11: DCAM.SUPPCD | F11: 取引先コード | G11: 文字列/9 | H11: △ | I11: WMS_コード変換テーブル.xlsxの「仕入先コード」 【商品マスタ統合プロジェクト】課題から設計内容の確認が必要
A12: 9 | C12: 納品先店舗・センターコード | D12: char/6 | E12: DCAM.WAREHOUSECD | F12: 検品倉庫コード | G12: 文字列/6 | H12: △ | I12: センターCD 「WMS_コード変換テーブル.xlsx」参考の「店舗コード」
A13: 10 | B13: ○ | C13: 発注伝票番号 | D13: int64_t/10 | E13: DCAM.SLIPNO | F13: 伝票番号（備考：発注伝票番号） | G13: 文字列/10 | H13: ○
A14: 11 | B14: ○ | C14: 納品経路区分 | D14: int16_t/5 | E14: DCAM.dlvroute_typeid | F14: （該当なし） | G14: ― | H14: ― | I14: GAPあり：現状TRIAL：1:店舗直納 2:センター納品 「WMS_コード変換テーブル.xlsx」参考
A15: 12 | B15: ○ | C15: 通過在庫区分 | D15: int16_t/5 | E15: DCAM.tcdc_typeid | F15: （該当なし） | G15: ― | H15: ― | I15: GAPあり：現状TRIAL：0:無指定 1:TC 2:預りDC 3:買取DC 「WMS_コード変換テーブル.xlsx」参考
A16: 13 | B16: ○ | C16: 納品形式区分 | D16: int16_t/5 | E16: DCAM.dlvway_typeid | F16: 納品形式区分 | G16: 文字列/2 | H16: △ | I16: GAPあり：現状TRIAL：01:総量 02:店別 MD基幹側マスタとのコード対応が必要。 「WMS_コード変換テーブル.xlsx」参考
A17: 14 | C17: 物流タイプ | D17: int16_t/5 | E17: DCAM.DISTRIBUTIONTYPE | F17: （該当なし） | G17: ― | H17: △ | I17: GAPあり：現状TRIAL：0:DC(5:DC補充) 1:TC店別 2:TC総量 3:店舗直納 4:預託在庫 DIFBRANCHPURCHASEINFO.(適用)納品方法
A18: 15 | C18: 温度帯区分 | D18: int16_t/5 | E18: DCAM.thermal_zone_typeid | F18: （該当なし） | G18: ― | H18: △ | I18: WMS側にソースなし。商品マスタから補完 PRODUCTS.管理温度帯コード
A19: 16 | C19: 検品チェック済みフラグ | D19: int8_t/1 | E19: 1 | F19: ― | G19: ― | H19: ― | I19: 現状TRIAL：1
A20: 17 | B20: ○ | C20: 原価金額(税抜) | D20: int64_t/19 | E20: 0 | F20: ― | G20: ― | H20: ― | I20: 現状TRIAL：0
A21: 18 | B21: ○ | C21: 売価金額(税込) | D21: int64_t/19 | E21: 0 | F21: ― | G21: ― | H21: ― | I21: 現状TRIAL：0
A22: 19 | B22: ○ | C22: 税区分 | D22: char/6 | E22: tax_typeid | F22: （該当なし） | G22: ― | H22: ― | I22: WMS側にソースなし。商品マスタから補完 MST_INCLUSIVE_TAX_TARGET.税フラグ
A23: 20 | B23: ○ | C23: 税率コード | D23: int16_t/5 | E23: tax_id | F23: （該当なし） | G23: ― | H23: ― | I23: WMS側にソースなし。商品マスタから補完 PRODUCTS.税率コード
A24: 21 | C24: 計上日 | D24: dbDate_t/8 | E24: CONVERT(VARCHAR(12),DCAM.INSPDATE,112) | F24: 計上日（実績確定日） | G24: 文字列/8 | H24: △
A25: 22 | C25: 削除フラグ | D25: int8_t/1 | E25: 0 | F25: ― | G25: ― | H25: ― | I25: 現状TRIAL：0
A26: 23 | C26: 登録日 | D26: dbDate_t/8 | E26: null | F26: ― | G26: ― | H26: ― | I26: 現状TRIAL：NULL
A27: 24 | C27: 登録時分秒 | D27: dbTime_t/6 | E27: null | F27: ― | G27: ― | H27: ― | I27: 現状TRIAL：NULL
A28: 25 | C28: 登録者コード | D28: char/16 | E28: DCAM.MAINTAINER | F28: （該当なし） | G28: ― | H28: ― | I28: 西友固定指定を勧める 現状トライアル:99000112
A29: 26 | C29: 登録機能コード | D29: char/16 | E29: null | F29: ― | G29: ― | H29: ― | I29: 現状TRIAL：NULL
A30: 27 | C30: 登録操作コード | D30: char/16 | E30: @ins_ope_id | F30: （該当なし） | G30: ― | H30: ― | I30: 西友固定指定を勧める 現状トライアル:oulm00101
A31: 28 | B31: ○ | C31: 行番号 | D31: int8_t/2 | E31: DCAM.SLIPLINENO | F31: 伝票行番号 | G31: 数値/3 | H31: △ | I31: MGAPあり：D基幹はint8_t(最大2桁=99まで)だが、WMSは3桁(最大999)。1伝票あたりの行数が100行を超えるケースがないか要確認（桁溢れリスク）。
A32: 29 | B32: ○ | C32: 数量（1000倍） | D32: int64_t/19 | E32: DCAM.PKGQTY*1000 | F32: 確定数量（バラ） | G32: 数値/7 | H32: △ | I32: GAPあり：WMSの確定数量（バラ、入荷数量の実績値）を1000倍した値をMD基幹へ設定するロジックが必要。
A33: 30 | B33: ○ | C33: 原単価（1000倍） | D33: int64_t/19 | E33: DCAM.COSTPRICE*1000 | F33: （該当なし） | G33: ― | H33: △ | I33: GAPあり：WMS側にソースなし。商品マスタから補完 DIFBRANCHPURCHASEINFO.(適用)発注原価(8)*1000
A34: 31 | B34: ○ | C34: 原価金額 | D34: int64_t/19 | E34: cast(round(COSTPRICE*PKGQTY,0) as bigint) | F34: （該当なし） | G34: ― | H34: △ | I34: 原単価*確定数量（バラ）
A35: 32 | B35: ○ | C35: 売価金額 | D35: int64_t/19 | E35: cast(round(SALEPRICE*PKGQTY,0) as bigint) | F35: （該当なし） | G35: ― | H35: △ | I35: 売単価*確定数量（バラ）
A36: 33 | B36: ○ | C36: 売単価 | D36: int32_t/10 | E36: DCAM.SALEPRICE | F36: （該当なし） | G36: ― | H36: △ | I36: GAPあり：WMS側にソースなし。商品マスタから補完 DIFBRANCHSALESINFO.(適用)基準売価(4)*1000
A37: 34 | B37: ○ | C37: JAN | D37: char/13 | E37: DCAM.PRODUCTCD | F37: 商品コード | G37: 文字列/14 | H37: △ | I37: 桁数差異（MD基幹13桁 / WMS14桁）
A38: 35 | C38: 理由区分 | D38: int16_t/5 | E38: DCAM.reason_typeid | F38: 欠品理由区分 | G38: 文字列/5 | H38: △ | I38: WMSは「欠品無し＝00000固定／欠品有り＝00001固定（取引先責）」の2値。MD基幹の理由区分マスタへのコード変換が必要。

Sheet 判定サマリ
A1: 項目マッピング 判定サマリ ― 仕入伝票（MD基幹⇔WMS IFSYLMS230R TC総量入荷実績データ／35項目）
A2: マスタ/IF区分 | B2: 判定 | C2: 件数 | D2: 割合 | E2: 主な内容・対応方針
A3: 仕入伝票（35項目） | B3: ○ 直接マッピング可 | C3: =COUNTIF('仕入伝票(purchase_slip)'!H4:H38,"○") -> 2 | D3: =TEXT(C3/COUNTA('仕入伝票(purchase_slip)'!A4:A38),"0%") -> 6% | E3: 計上日(名称一致)、発注伝票番号(発注伝票番号として意味一致)の2項目のみ。
A4: 仕入伝票（35項目） | B4: △ 変換・加工が必要 | C4: =COUNTIF('仕入伝票(purchase_slip)'!H4:H38,"△") -> 16 | D4: =TEXT(C4/COUNTA('仕入伝票(purchase_slip)'!A4:A38),"0%") -> 46% | E4: 部門コード階層結合、数量1000倍変換、JAN桁数変換、伝票区分候補データの変換、行番号桁数変換 等
A5: 仕入伝票（35項目） | B5: ✕ GAPあり | C5: =COUNTIF('仕入伝票(purchase_slip)'!H4:H38,"✕") -> 1 | D5: =TEXT(C5/COUNTA('仕入伝票(purchase_slip)'!A4:A38),"0%") -> 3% | E5: 原単価・原価金額・売単価・売価金額(単価情報がWMSに存在しない)、伝票区分・伝票番号・通過在庫区分・温度帯区分の対応未定義
A6: 仕入伝票（35項目） | B6: ― 固定値/NULL/対象外 | C6: =COUNTIF('仕入伝票(purchase_slip)'!H4:H38,"―") -> 15 | D6: =TEXT(C6/COUNTA('仕入伝票(purchase_slip)'!A4:A38),"0%") -> 43% | E6: 伝票ID等MD基幹内部採番項目、税区分・税率コード(必須緩和済)、登録者情報等の自動設定項目

Sheet 入出力仕様(Hitluster)
A1: ドキュメント名 | D1: 項目移送表
A2: インターフェースID | D2: IFSYLMS230R
A3: インターフェース名 | D3: TC総量入荷実績データ
A4: 連携方式 | B4: インターフェース方向 | D4: WMS⇒MD基幹システム
B5: データ連携方式 | D5: SFTP（GET）
B6: 全件／差分 | D6: 差分更新
A7: ファイル | B7: ファイル名 | D7: =D2&"_倉庫コード(6桁)_YYYYMMDDhhmmss_NNNNNN(連番6桁).DAT" -> IFSYLMS230R_倉庫コード(6桁)_YYYYMMDDhhmmss_NNNNNN(連番6桁).DAT
B8: フォーマット | D8: 固定長
B9: 文字コード | D9: ShiftJIS
F10: =SUM(F13:F112) -> 512
A11: 編集仕様 （【処理名】を記述） | B11: WMS
B12: No | C12: 項目名称 | D12: 項目ＩＤ | E12: タイプ | F12: バイト | G12: 必須 | H12: 実績 | I12: 備考
B13: 1 | C13: データ区分 | E13: 文字列 | F13: 2 | I13: "23"固定
B14: 2 | C14: 処理日 | E14: 文字列 | F14: 8 | G14: ● | I14: MD基幹管理項目
B15: 3 | C15: 入力連番 | E15: 数値 | F15: 8 | G15: ● | I15: MD基幹管理項目
B16: 4 | C16: 検品倉庫コード | E16: 文字列 | F16: 6 | G16: ● | I16: 検品TC倉庫コード
B17: 5 | C17: 取引先コード | E17: 文字列 | F17: 9 | G17: ● | I17: 取引先コード6桁＋枝番3桁(デパ2桁＋連番1桁)
B18: 6 | C18: 納品形態区分 | E18: 文字列 | F18: 2 | I18: 12：TC総量入荷 10：TC店別入荷
B19: 7 | C19: 便区分 | E19: 文字列 | F19: 2 | I19: 01：1便、02：2便
B20: 8 | C20: 発注区分 | E20: 文字列 | F20: 2 | G20: ● | I20: WMSからMD基幹へ送信する際にMD基幹内で管理している以下コードへ読み替える 01：定番 → 0：通常 22：特売 → 2：特売 21：本部発注 → 7：本部
B21: 9 | C21: 発注日 | E21: 文字列 | F21: 8 | G21: ● | I21: YYYYMMDD
B22: 10 | C22: 検品倉庫着荷指定日 | E22: 文字列 | F22: 8 | G22: ● | I22: YYYYMMDD 検品TC倉庫作業予定日
B23: 11 | C23: 計上日 | E23: 文字列 | F23: 8 | G23: ● | H23: ● | I23: YYYYMMDD 実績確定日
B24: 12 | C24: 部門グループコード | E24: 文字列 | F24: 2 | G24: ● | I24: Division
B25: 13 | C25: 部門コード | E25: 文字列 | F25: 2 | G25: ● | I25: Depa
B26: 14 | C26: 中分類コード | E26: 文字列 | F26: 2 | I26: 西友ライン
B27: 15 | C27: 小分類コード | E27: 文字列 | F27: 4 | I27: Fineline
B28: 16 | C28: 伝票番号 | E28: 文字列 | F28: 10 | G28: ● | I28: 発注伝票番号
B29: 17 | C29: 伝票行番号 | E29: 数値 | F29: 3 | G29: ● | I29: 行番号
B30: 18 | C30: 商品コード | E30: 文字列 | F30: 14 | G30: ●
B31: 19 | C31: 発注数量（バラ） | E31: 数値 | F31: 7
B32: 20 | C32: 発注単位数 | E32: 数値 | F32: 7 | G32: ●
B33: 21 | C33: 総重量 | E33: 数値 | F33: 9 | G33: ● | H33: ● | I33: 不定貫品の場合のみ ※整数部6桁小数部3桁
B34: 22 | C34: 確定数量（バラ） | E34: 数値 | F34: 7 | G34: ● | H34: ● | I34: 入荷数量
B35: 23 | C35: 欠品理由区分 | E35: 文字列 | F35: 5 | G35: ● | H35: ● | I35: 欠品無しの場合、00000固定 欠品有りの場合、00001固定（取引先責）
B36: 24 | C36: 欠品数量（バラ） | E36: 数値 | F36: 7 | G36: ● | H36: ● | I36: 欠品無しの場合、0000000固定 欠品有りの場合、XXXXXXX（欠品数量）
B37: 25 | C37: FILLER | E37: 文字列 | F37: =512-SUM(F13:F36) -> 370 | I37: 半角スペース

Sheet 項目比較
B1: トライアル | D1: WMS(Hitluster)
B2: 納品日 | C2: CONVERT(VARCHAR(12) , DCAM.INSPDATE, 112 ) | D2: 検品倉庫着荷指定日 | E2: YYYYMMDD 検品TC倉庫作業予定日
B3: 伝票ID | C3: ,NULL
B4: 伝票履歴先頭ID | C4: ,NULL
B5: 伝票区分 | C5: ,DCAM.SLIPDIVISION
B6: 伝票番号 | C6: ,DCAM.SLIPNO | E6: 発注伝票番号
B7: 店舗コード | C7: ,DCAM.DEMANDCD | D7: 検品倉庫コード | E7: 検品TC倉庫コード
B8: 部門コード | C8: ,DCAM.DEPARTMENTCD | D8: 部門コード | E8: Depa
B9: 仕入先コード | C9: ,DCAM.SUPPCD | D9: 取引先コード | E9: 取引先コード6桁＋枝番3桁(デパ2桁＋連番1桁)
B10: 納品先店舗・センターコード | C10: ,DCAM.WAREHOUSECD
B11: 発注伝票番号 | C11: ,DCAM.SLIPNO | D11: 伝票番号 | E11: 発注伝票番号
B12: 納品経路区分 | C12: ,DCAM.dlvroute_typeid | F12: 1:店舗直納 2:センター納品
B13: 通過在庫区分 | C13: ,DCAM.tcdc_typeid | F13: 0:無指定 1:TC 2:預りDC 3:買取DC
B14: 納品形式区分 | C14: ,DCAM.dlvway_typeid | D14: 納品形態区分 | F14: 1:総量 2:店別
B15: 物流タイプ | C15: DCAM.DISTRIBUTIONTYPE | F15: 0:DC 1:TC店別 2:TC総量 3:店舗直納 4:預託在庫 5:DC補充
B16: 温度帯区分 | C16: DCAM.thermal_zone_typeid
B17: 検品チェック済みフラグ | C17: ,1
B18: 原価金額(税抜) | C18: ,0
B19: 売価金額(税込) | C19: ,0
B20: 税区分 | C20: ,tax_typeid
B21: 税率コード | C21: ,tax_id
B22: 計上日 | C22: ,CONVERT(VARCHAR(12),DCAM.INSPDATE,112) | D22: 計上日 | E22: YYYYMMDD 実績確定日
B23: 削除フラグ | C23: ,0
B24: 登録日 | C24: ,null
B25: 登録時分秒 | C25: ,null
B26: 登録者コード | C26: ,DCAM.MAINTAINER
B27: 登録機能コード | C27: ,null
B28: 登録操作コード | C28: ,@ins_ope_id
B29: 行番号 | C29: ,DCAM.SLIPLINENO | D29: 伝票行番号 | E29: 行番号
B30: 数量（1000倍） | C30: ,DCAM.PKGQTY*1000 | D30: 確定数量（バラ） | E30: 入荷数量
B31: 原単価（1000倍） | C31: ,DCAM.COSTPRICE*1000
B32: 原価金額 | C32: ,cast(round(COSTPRICE*PKGQTY,0) as bigint)
B33: 売価金額 | C33: ,cast(round(SALEPRICE*PKGQTY,0) as bigint)
B34: 売単価 | C34: ,DCAM.SALEPRICE
B35: JAN | C35: ,DCAM.PRODUCTCD | D35: 商品コード
B36: 理由区分 | C36: ,DCAM.reason_typeid | D36: 欠品理由区分 | E36: 欠品無しの場合、00000固定 欠品有りの場合、00001固定（取引先責）
D38: 発注区分 | E38: WMSからMD基幹へ送信する際にMD基幹内で管理している以下コードへ読み替える 01：定番 → 0：通常 22：特売 → 2：特売 21：本部発注 → 7：本部
D39: 欠品数量（バラ） | E39: 欠品無しの場合、0000000固定 欠品有りの場合、XXXXXXX（欠品数量）
D40: FILLER | E40: 半角スペース
D41: 総重量 | E41: 不定貫品の場合のみ ※整数部6桁小数部3桁
...

Sheet Sheet2
B1: トライアル(基幹) | C1: トライアルWMS(LOMOS)
C3: FTP.dbo.wrk_Receiver_DCShippingResult | D3: FTP.dbo.wrk_Receiver_DCShippingResult | E3: FTP.dbo.wrk_Receiver_TCShippingResult
C4: ↓ | D4: ↓ | E4: ↓ | F4: 更新状態
C5: OrderDB.dbo.TB_DCArrivalPlanDataAccum | D5: OrderDB.dbo.TB_OrderSlipDetailAccum | E5: OrderDB.dbo.TB_TCArrivalPlanDataAccum | F5: データ更新日時 | L5: SELECT delivery_date, COALESCE(cast(slipid as varchar),'') as slipid, " +
A6: 検品倉庫着荷指定日 | B6: 納品日 | C6: CONVERT(VARCHAR(12) , DCAM.INSPDATE, 112 ) | D6: ,CONVERT(VARCHAR(12),ArriveDate,112) | E6: ,CONVERT(VARCHAR(12),#SLIT.INSPDATENew,112) | F6: 納品日 | H6: delivery_date | L6: "COALESCE(cast(slip_hisid as varchar),'') as slip_hisid, slip_division, " +
A7: NULL | B7: 伝票ID | C7: ,NULL | D7: ,null | E7: ,null | F7: 伝票ID | H7: , COALESCE(cast(slipid as varchar),'') as slipid | L7: "slip_no, branchcd, departmentcd, suppliercd, through_branchcd, " +
A8: NULL | B8: 伝票履歴先頭ID | C8: ,NULL | D8: ,null | E8: ,null | F8: 伝票履歴先頭ID | H8: , " +"COALESCE(cast(slip_hisid as varchar),'') as slip_hisid | L8: "order_slipnumber, COALESCE(cast(dlvroute_typeid as varchar),'') as dlvroute_typeid, " +
B9: 伝票区分 | C9: ,DCAM.SLIPDIVISION | D9: ,SLIPDIVISION | E9: ,TCAM.SLIPDIVISION | F9: 伝票区分 | H9: , slip_division | L9: "COALESCE(cast(tcdc_typeid as varchar),'') as tcdc_typeid, " +
A10: 伝票番号 | B10: 伝票番号 | C10: ,DCAM.SLIPNO | D10: ,ORDM.SLIPNO | E10: ,TCAM.SLIPNO | F10: 伝票NO | H10: , " +"slip_no | L10: "COALESCE(cast(dlvway_typeid as varchar),'') as dlvway_typeid, distributiontype, " +
A11: 検品TC倉庫コード | B11: 店舗コード | C11: ,DCAM.DEMANDCD | D11: ,ORDM.DEMANDCD | E11: ,TCAM.DEMANDCD | F11: 店CD | H11: , branchcd | L11: "COALESCE(cast(thermal_zone_typeid as varchar),'') as thermal_zone_typeid, " +
A12: 部門コード | B12: 部門コード | C12: ,DCAM.DEPARTMENTCD | D12: ,DEPARTMENTCD | E12: ,TCAM.DEPARTMENTCD | F12: 部門CD | H12: , departmentcd | L12: "f_inspect_checked, abs(o_am) as o_am, abs(s_am) as s_am, tax_typeid, tax_id, " +
A13: 取引先コード | B13: 仕入先コード | C13: ,DCAM.SUPPCD | D13: ,SUPPCD | E13: ,TCAM.SUPPCD | F13: ベンダーCD | H13: , suppliercd | L13: "count_date, f_del, ins_date, COALESCE(cast(ins_time as varchar),'') as ins_time, " +
A14: 検品倉庫コード | B14: 納品先店舗・センターコード | C14: ,DCAM.WAREHOUSECD | D14: ,WAREHOUSECD | E14: ,TCAM.WAREHOUSECD | F14: 納品先店舗・センターコード | H14: , through_branchcd | L14: "COALESCE(cast(ins_user_id as varchar),'') as ins_user_id, " +
A15: 伝票番号 | B15: 発注伝票番号 | C15: ,DCAM.SLIPNO | D15: ,null | E15: ,TCAM.SLIPNO | F15: 発注伝票番号 | H15: , " + "order_slipnumber | L15: "COALESCE(cast(ins_func_id as varchar),'') as ins_func_id, " +
B16: 納品経路区分 | C16: ,DCAM.dlvroute_typeid | D16: ,dlvroute_typeid | E16: ,dlvroute_typeid | F16: 納品経路区分 | H16: , COALESCE(cast(dlvroute_typeid as varchar),'') as dlvroute_typeid | L16: "COALESCE(cast(ins_ope_id as varchar),'') as ins_ope_id, slip_detail_number, " +
B17: 通過在庫区分 | C17: ,DCAM.tcdc_typeid | D17: ,tcdc_typeid | E17: ,tcdc_typeid | F17: 通過在庫区分 | H17: , " + "COALESCE(cast(tcdc_typeid as varchar),'') as tcdc_typeid | L17: "abs(delivery_qty) as delivery_qty, cost_price, abs(dlv_am) as dlv_am, " +
A18: 納品形態区分 | B18: 納品形式区分 | C18: ,DCAM.dlvway_typeid | D18: ,dlvway_typeid | E18: ,dlvway_typeid | F18: 納品形式区分 | H18: , " +"COALESCE(cast(dlvway_typeid as varchar),'') as dlvway_typeid | L18: "abs(sales_am) as sales_am, sales_price, product_cd, " +
B19: 物流タイプ | C19: ,DCAM.DISTRIBUTIONTYPE | D19: ,DISTRIBUTIONTYPE | E19: ,TCAM.DISTRIBUTIONTYPE | F19: 物流タイプ | H19: , distributiontype | L19: "COALESCE(cast(reason_typeid as varchar),'') as reason_typeid FROM " +
B20: 温度帯区分 | C20: ,DCAM.thermal_zone_typeid | D20: ,thermal_zone_typeid | E20: ,thermal_zone_typeid | F20: 温度帯区分 | H20: , " + "COALESCE(cast(thermal_zone_typeid as varchar),'') as thermal_zone_typeid | L20: tableName + " where update_status = 1 ORDER BY slip_no,slip_detail_number",
A21: ,1 | B21: 検品チェック済みフラグ | C21: ,1 | D21: ,1 | E21: ,1 | F21: 検品チェック済みフラグ | H21: , " +"f_inspect_checked
A22: ,0 | B22: 原価金額(税抜) | C22: ,0 | D22: ,0 | E22: ,0 | F22: 原価金額(税抜) | H22: , abs(o_am) as o_am
A23: ,0 | B23: 売価金額(税込) | C23: ,0 | D23: ,0 | E23: ,0 | F23: 売価金額(税込) | H23: , abs(s_am) as s_am
B24: 税区分 | C24: ,tax_typeid | D24: ,tax_typeid | E24: ,tax_typeid | F24: 税区分 | H24: , tax_typeid
B25: 税率コード | C25: ,tax_id | D25: ,tax_id | E25: ,tax_id | F25: 税率コード | H25: , tax_id
A26: 計上日 | B26: 計上日 | C26: ,CONVERT(VARCHAR(12),DCAM.INSPDATE,112) | D26: ,CONVERT(VARCHAR(12),ArriveDate,112) | E26: ,CONVERT(VARCHAR(12),#SLIT.INSPDATENew,112) | F26: 計上日 | H26: , " +"count_date
A27: ,0 | B27: 削除フラグ | C27: ,0 | D27: ,0 | E27: ,0 | F27: 削除フラグ | H27: , f_del
A28: ,null | B28: 登録日 | C28: ,null | D28: ,null | E28: ,null | F28: 登録日 | H28: , ins_date
A29: ,null | B29: 登録時分秒 | C29: ,null | D29: ,null | E29: ,null | F29: 登録時刻 | H29: , COALESCE(cast(ins_time as varchar),'') as ins_time
A30: 99000112 | B30: 登録者コード | C30: ,DCAM.MAINTAINER | D30: ,ORDM.MAINTAINER | E30: ,TCAM.MAINTAINER | F30: 登録者コード | H30: , " + "COALESCE(cast(ins_user_id as varchar),'') as ins_user_id | L30: TMDLI0120 | M30: wrk_tomd_transfer
A31: ,null | B31: 登録機能コード | C31: ,null | D31: ,null | E31: ,null | F31: 登録機能ID | H31: , " + "COALESCE(cast(ins_func_id as varchar),'') as ins_func_id | L31: TMDLI0110 | M31: wrk_tomd_purchase
A32: oulm00101 | B32: 登録操作コード | C32: ,@ins_ope_id | D32: ,@ins_ope_id | E32: ,@ins_ope_id | F32: 登録操作ID | H32: , " +"COALESCE(cast(ins_ope_id as varchar),'') as ins_ope_id
A33: 伝票行番号 | B33: 行番号 | C33: ,DCAM.SLIPLINENO | D33: ,SLIPLINENO | E33: ,TCAM.SLIPLINENO | F33: 行NO | H33: , slip_detail_number
A34: 確定数量（バラ） | B34: 数量（1000倍） | C34: ,DCAM.PKGQTY*1000 | D34: ,PKGQTY*1000 | E34: ,TCAM.PKGQTY*1000 | F34: 納品数 | H34: , " +"abs(delivery_qty) as delivery_qty
B35: 原単価（1000倍） | C35: ,DCAM.COSTPRICE*1000 | D35: ,ITEMCOSTPRICE*1000 | E35: ,TCAM.COSTPRICE*1000 | F35: 原単価 | H35: , cost_price
A36: 原単価*確定数量（バラ） | B36: 原価金額 | C36: ,cast(round(COSTPRICE*PKGQTY,0) as bigint) | D36: ,cast(round(ITEMCOSTPRICE*PKGQTY,0) as bigint) | E36: ,cast(round(PKGQTY*COSTPRICE,0) as bigint) | F36: 原価金額 | H36: , abs(dlv_am) as dlv_am
A37: 売単価*確定数量（バラ） | B37: 売価金額 | C37: ,cast(round(SALEPRICE*PKGQTY,0) as bigint) | D37: ,cast(round(ITEMSALEPRICE*PKGQTY,0) as bigint) | E37: ,cast(round(PKGQTY*SALEPRICE,0) as bigint) | F37: 売価金額 | H37: , " +"abs(sales_am) as sales_am
B38: 売単価 | C38: ,DCAM.SALEPRICE | D38: ,ITEMSALEPRICE | E38: ,TCAM.SALEPRICE | F38: 売単価 | H38: , sales_price
A39: 商品コード | B39: JAN | C39: ,DCAM.PRODUCTCD | D39: ,PRODUCTCD | E39: ,TCAM.PRODUCTCD | F39: 商品コード | H39: , product_cd
A40: 欠品理由区分 | B40: 理由区分 | C40: ,DCAM.reason_typeid | D40: ,reason_typeid | E40: ,reason_typeid | F40: 理由区分 | H40: , " +"COALESCE(cast(reason_typeid as varchar),'') as reason_typeid

Sheet サンプルデータ
B1: TC店舗振替実績データ
B2: IFSYLMS240R_倉庫コード_YYYYMMDDhhmmss_連番.DAT | X2: 店舗
B3: IFSYLMS240R_007451_20260625130454_015686.DAT_20260625133500
B4: 2 | C4: 8 | D4: 8 | E4: 6 | F4: 6 | G4: 9 | H4: 2 | I4: 2 | J4: 2 | K4: 8 | L4: 8 | M4: 8 | N4: 8 | O4: 8 | P4: 2 | Q4: 2 | R4: 2 | S4: 4 | T4: 10 | U4: 3 | V4: 3 | W4: 14 | X4: 6 | Y4: 7 | Z4: 7 | AA4: 9 | AB4: 7 | AC4: 5 | AD4: 7 | AE4: 9 | AF4: 330
B5: データ区分 | C5: 処理日 | D5: 入力連番 | E5: 検品倉庫コード | F5: 管轄倉庫コード | G5: 取引先コード | H5: 納品形態区分 | I5: 便区分 | J5: 発注区分 | K5: 発注日 | L5: 検品倉庫着荷指定日 | M5: 管轄倉庫着荷指定日 | N5: 店舗着荷指定日 | O5: 計上日 | P5: 部門グループコード | Q5: 部門コード | R5: 中分類コード | S5: 小分類コード | T5: 伝票番号 | U5: 伝票行番号 | V5: 伝票行枝番 | W5: 商品コード | X5: 出荷先コード | Y5: 出荷数量（バラ） | Z5: 出荷単位数 | AA5: 店別重量 | AB5: 確定数量（バラ） | AC5: 欠品理由区分 | AD5: 欠品数量（バラ） | AE5: 欠品重量 | AF5: FILLER
B6: 24 | C6: 20260606 | D6: 00168347 | E6: 007451 | F6: 007451 | G6: 001401902 | H6: 10 | I6: 01 | J6: 7 | K6: 20260606 | L6: 20260625 | M6: 20260625 | N6: 20260625 | O6: 20260625 | P6: 28 | Q6: 90 | R6: 08 | S6: 1555 | T6: 0008365291 | U6: 001 | V6: 001 | W6: 4901820194176 | X6: 003338 | Y6: 0000034 | Z6: 0000002 | AA6: 000000000 | AB6: 0000034 | AC6: 00000 | AD6: 0000000 | AE6: 000000000
B7: 24 | C7: 20260606 | D7: 00168347 | E7: 007451 | F7: 007451 | G7: 001401902 | H7: 10 | I7: 01 | J7: 7 | K7: 20260606 | L7: 20260625 | M7: 20260625 | N7: 20260625 | O7: 20260625 | P7: 28 | Q7: 90 | R7: 08 | S7: 1555 | T7: 0008365291 | U7: 001 | V7: 002 | W7: 4901820194176 | X7: 003351 | Y7: 0000018 | Z7: 0000002 | AA7: 000000000 | AB7: 0000018 | AC7: 00000 | AD7: 0000000 | AE7: 000000000
B8: 24 | C8: 20260606 | D8: 00168347 | E8: 007451 | F8: 007451 | G8: 001401902 | H8: 10 | I8: 01 | J8: 7 | K8: 20260606 | L8: 20260625 | M8: 20260625 | N8: 20260625 | O8: 20260625 | P8: 28 | Q8: 90 | R8: 08 | S8: 1555 | T8: 0008365291 | U8: 001 | V8: 003 | W8: 4901820194176 | X8: 003387 | Y8: 0000024 | Z8: 0000002 | AA8: 000000000 | AB8: 0000024 | AC8: 00000 | AD8: 0000000 | AE8: 000000000
B9: 24 | C9: 20260606 | D9: 00168347 | E9: 007451 | F9: 007451 | G9: 001401902 | H9: 10 | I9: 01 | J9: 7 | K9: 20260606 | L9: 20260625 | M9: 20260625 | N9: 20260625 | O9: 20260625 | P9: 28 | Q9: 90 | R9: 08 | S9: 1555 | T9: 0008365291 | U9: 001 | V9: 004 | W9: 4901820194176 | X9: 003388 | Y9: 0000022 | Z9: 0000002 | AA9: 000000000 | AB9: 0000022 | AC9: 00000 | AD9: 0000000 | AE9: 000000000
B10: 24 | C10: 20260606 | D10: 00168347 | E10: 007451 | F10: 007451 | G10: 001401902 | H10: 10 | I10: 01 | J10: 7 | K10: 20260606 | L10: 20260625 | M10: 20260625 | N10: 20260625 | O10: 20260625 | P10: 28 | Q10: 90 | R10: 08 | S10: 1555 | T10: 0008365291 | U10: 001 | V10: 005 | W10: 4901820194176 | X10: 003389 | Y10: 0000038 | Z10: 0000002 | AA10: 000000000 | AB10: 0000038 | AC10: 00000 | AD10: 0000000 | AE10: 000000000
B11: 24 | C11: 20260606 | D11: 00168347 | E11: 007451 | F11: 007451 | G11: 001401902 | H11: 10 | I11: 01 | J11: 7 | K11: 20260606 | L11: 20260625 | M11: 20260625 | N11: 20260625 | O11: 20260625 | P11: 28 | Q11: 90 | R11: 08 | S11: 1555 | T11: 0008365291 | U11: 001 | V11: 006 | W11: 4901820194176 | X11: 003394 | Y11: 0000028 | Z11: 0000002 | AA11: 000000000 | AB11: 0000028 | AC11: 00000 | AD11: 0000000 | AE11: 000000000
B12: 24 | C12: 20260606 | D12: 00168347 | E12: 007451 | F12: 007451 | G12: 001401902 | H12: 10 | I12: 01 | J12: 7 | K12: 20260606 | L12: 20260625 | M12: 20260625 | N12: 20260625 | O12: 20260625 | P12: 28 | Q12: 90 | R12: 08 | S12: 1555 | T12: 0008365291 | U12: 001 | V12: 007 | W12: 4901820194176 | X12: 003395 | Y12: 0000040 | Z12: 0000002 | AA12: 000000000 | AB12: 0000040 | AC12: 00000 | AD12: 0000000 | AE12: 000000000
B13: 24 | C13: 20260606 | D13: 00168347 | E13: 007451 | F13: 007451 | G13: 001401902 | H13: 10 | I13: 01 | J13: 7 | K13: 20260606 | L13: 20260625 | M13: 20260625 | N13: 20260625 | O13: 20260625 | P13: 28 | Q13: 90 | R13: 08 | S13: 1555 | T13: 0008365291 | U13: 001 | V13: 008 | W13: 4901820194176 | X13: 003412 | Y13: 0000040 | Z13: 0000002 | AA13: 000000000 | AB13: 0000040 | AC13: 00000 | AD13: 0000000 | AE13: 000000000
B14: 24 | C14: 20260606 | D14: 00168347 | E14: 007451 | F14: 007451 | G14: 001401902 | H14: 10 | I14: 01 | J14: 7 | K14: 20260606 | L14: 20260625 | M14: 20260625 | N14: 20260625 | O14: 20260625 | P14: 28 | Q14: 90 | R14: 08 | S14: 1555 | T14: 0008365291 | U14: 001 | V14: 009 | W14: 4901820194176 | X14: 003414 | Y14: 0000026 | Z14: 0000002 | AA14: 000000000 | AB14: 0000026 | AC14: 00000 | AD14: 0000000 | AE14: 000000000
B15: 24 | C15: 20260606 | D15: 00168347 | E15: 007451 | F15: 007451 | G15: 001401902 | H15: 10 | I15: 01 | J15: 7 | K15: 20260606 | L15: 20260625 | M15: 20260625 | N15: 20260625 | O15: 20260625 | P15: 28 | Q15: 90 | R15: 08 | S15: 1555 | T15: 0008365291 | U15: 001 | V15: 010 | W15: 4901820194176 | X15: 003416 | Y15: 0000034 | Z15: 0000002 | AA15: 000000000 | AB15: 0000034 | AC15: 00000 | AD15: 0000000 | AE15: 000000000
B16: 24 | C16: 20260606 | D16: 00168347 | E16: 007451 | F16: 007451 | G16: 001401902 | H16: 10 | I16: 01 | J16: 7 | K16: 20260606 | L16: 20260625 | M16: 20260625 | N16: 20260625 | O16: 20260625 | P16: 28 | Q16: 90 | R16: 08 | S16: 1555 | T16: 0008365291 | U16: 001 | V16: 011 | W16: 4901820194176 | X16: 003417 | Y16: 0000038 | Z16: 0000002 | AA16: 000000000 | AB16: 0000038 | AC16: 00000 | AD16: 0000000 | AE16: 000000000
B17: 24 | C17: 20260606 | D17: 00168347 | E17: 007451 | F17: 007451 | G17: 001401902 | H17: 10 | I17: 01 | J17: 7 | K17: 20260606 | L17: 20260625 | M17: 20260625 | N17: 20260625 | O17: 20260625 | P17: 28 | Q17: 90 | R17: 08 | S17: 1555 | T17: 0008365291 | U17: 001 | V17: 012 | W17: 4901820194176 | X17: 003419 | Y17: 0000042 | Z17: 0000002 | AA17: 000000000 | AB17: 0000042 | AC17: 00000 | AD17: 0000000 | AE17: 000000000
... B25: 24 | C25: 20260606 | D25: 00168347 | E25: 007451 | F25: 007451 | G25: 001401902 | H25: 10 | I25: 01 | J25: 7 | K25: 20260606 | L25: 20260625 | M25: 20260625 | N25: 20260625 | O25: 20260625 | P25: 28 | Q25: 90 | R25: 08 | S25: 1555 | T25: 0008365291 | U25: 001 | V25: 020 | W25: 4901820194176 | X25: 005261 | Y25: 0000048 | Z25: 0000002 | AA25: 000000000 | AB25: 0000048 | AC25: 00000 | AD25: 0000000 | AE25: 000000000
B28: 2 | C28: 8 | D28: 8 | E28: 6 | F28: 9 | G28: 2 | H28: 2 | I28: 2 | J28: 8 | K28: 8 | L28: 8 | M28: 2 | N28: 2 | O28: 2 | P28: 4 | Q28: 10 | R28: 3 | S28: 14 | T28: 7 | U28: 7 | V28: 9 | W28: 7 | X28: 5 | Y28: 7 | Z28: 370
B29: TC総量入荷実績データ
B30: IFSYLMS230R_倉庫コード_YYYYMMDDhhmmss_連番.DAT
B31: IFSYLMS230R_007451_20260625130453_015685.DAT_20260625133500
E32: 松本通過センター
B33: データ区分 | C33: 処理日 | D33: 入力連番 | E33: 検品倉庫コード | F33: 取引先コード | G33: 納品形態区分 | H33: 便区分 | I33: 発注区分 | J33: 発注日 | K33: 検品倉庫着荷指定日 | L33: 計上日 | M33: 部門グループコード | N33: 部門コード | O33: 中分類コード | P33: 小分類コード | Q33: 伝票番号 | R33: 伝票行番号 | S33: 商品コード | T33: 発注数量（バラ） | U33: 発注単位数 | V33: 総重量 | W33: 確定数量（バラ） | X33: 欠品理由区分 | Y33: 欠品数量（バラ） | Z33: FILLER
B34: 23 | C34: 20260606 | D34: 00168347 | E34: 007451 | F34: 001401902 | G34: 10 | H34: 01 | I34: 7 | J34: 20260606 | K34: 20260625 | L34: 20260625 | M34: 28 | N34: 90 | O34: 08 | P34: 1555 | Q34: 0008365291 | R34: 001 | S34: 4901820194176 | T34: 0000652 | U34: 0000002 | V34: 000000000 | W34: 0000652 | X34: 00000 | Y34: 0000000
B35: 23 | C35: 20260606 | D35: 00168347 | E35: 007451 | F35: 001401902 | G35: 10 | H35: 01 | I35: 7 | J35: 20260606 | K35: 20260625 | L35: 20260625 | M35: 28 | N35: 90 | O35: 08 | P35: 1550 | Q35: 0008365291 | R35: 002 | S35: 4901820366016 | T35: 0000458 | U35: 0000002 | V35: 000000000 | W35: 0000458 | X35: 00000 | Y35: 0000000
B36: 23 | C36: 20260606 | D36: 00168347 | E36: 007451 | F36: 001401902 | G36: 10 | H36: 01 | I36: 7 | J36: 20260606 | K36: 20260625 | L36: 20260625 | M36: 28 | N36: 90 | O36: 08 | P36: 1535 | Q36: 0008365291 | R36: 003 | S36: 4901820471215 | T36: 0000298 | U36: 0000002 | V36: 000000000 | W36: 0000298 | X36: 00000 | Y36: 0000000
B39: DC出荷実績データ
B40: IFSYLMS220R_倉庫コード_YYYYMMDDhhmmss_連番.DAT | W40: 店舗
B41: IFSYLMS220R_007452_20260625130248_037858.DAT_20260625130500
E42: 三郷在庫センター | H42: DC店別出荷(買取)
B43: 2 | C43: 8 | D43: 8 | E43: 6 | F43: 6 | G43: 9 | H43: 2 | I43: 2 | J43: 2 | K43: 8 | L43: 8 | M43: 8 | N43: 8 | O43: 8 | P43: 2 | Q43: 2 | R43: 2 | S43: 4 | T43: 10 | U43: 3 | V43: 14 | W43: 6 | X43: 7 | Y43: 7 | Z43: 7 | AA43: 5 | AB43: 7 | AC43: 9 | AD43: 342
B44: データ区分 | C44: 処理日 | D44: 入力連番 | E44: 検品倉庫コード | F44: 管轄倉庫コード | G44: 取引先コード | H44: 納品形態区分 | I44: 便区分 | J44: 発注区分 | K44: 発注日 | L44: 検品倉庫着荷指定日 | M44: 管轄倉庫着荷指定日 | N44: 店舗着荷指定日 | O44: 計上日 | P44: 部門グループコード | Q44: 部門コード | R44: 中分類コード | S44: 小分類コード | T44: 伝票番号 | U44: 伝票行番号 | V44: 商品コード | W44: 出荷先コード | X44: 出荷数量（バラ） | Y44: 出荷単位数 | Z44: 確定数量（バラ） | AA44: 欠品理由区分 | AB44: 欠品数量（バラ） | AC44: 移動平均単価 | AD44: FILLER
B45: 22 | C45: 20260623 | D45: 00002052 | E45: 007452 | F45: 007428 | G45: 000001900 | H45: 51 | I45: 01 | J45: 0 | K45: 20260623 | L45: 20260625 | M45: 20260625 | N45: 20260625 | O45: 20260624 | P45: 28 | Q45: 90 | R45: 01 | S45: 0570 | T45: 0008512196 | U45: 006 | V45: 4522646037838 | W45: 000004 | X45: 0000012 | Y45: 0000012 | Z45: 0000012 | AA45: 00000 | AB45: 0000000 | AC45: 000175200
B46: 22 | C46: 20260623 | D46: 00002054 | E46: 007452 | F46: 007411 | G46: 000001900 | H46: 51 | I46: 01 | J46: 0 | K46: 20260623 | L46: 20260625 | M46: 20260625 | N46: 20260625 | O46: 20260624 | P46: 28 | Q46: 90 | R46: 01 | S46: 0570 | T46: 0008512198 | U46: 001 | V46: 4522646037821 | W46: 000015 | X46: 0000012 | Y46: 0000012 | Z46: 0000012 | AA46: 00000 | AB46: 0000000 | AC46: 000175200
B47: 22 | C47: 20260623 | D47: 00002054 | E47: 007452 | F47: 007411 | G47: 000001900 | H47: 51 | I47: 01 | J47: 0 | K47: 20260623 | L47: 20260625 | M47: 20260625 | N47: 20260625 | O47: 20260624 | P47: 28 | Q47: 90 | R47: 01 | S47: 0570 | T47: 0008512198 | U47: 002 | V47: 4522646037838 | W47: 000015 | X47: 0000012 | Y47: 0000012 | Z47: 0000012 | AA47: 00000 | AB47: 0000000 | AC47: 000175200
B50: DC入荷実績データ
B51: IFSYLMS210R_倉庫コード_YYYYMMDDhhmmss_連番.DAT
B52: IFSYLMS210R_007455_20260625170526_027705.DAT_20260625173500
E53: 仙台在庫センター | G53: 30：DC総量入荷(買取) | H53: 本部
...

Sheet Sheet3
A1: 伝票番号 | D1: 伝票番号 | I1: 230 | J1: 210
A2: 0008360417 | D2: 0008360417 | E2: =D2=A2 -> TRUE | I2: データ区分 | J2: データ区分 | K2: =J2=I2 -> TRUE
A3: 0008360422 | D3: 0008360422 | E3: =D3=A3 -> TRUE | I3: 処理日 | J3: 処理日 | K3: =J3=I3 -> TRUE
A4: 0008360444 | D4: 0008360444 | E4: =D4=A4 -> TRUE | I4: 入力連番 | J4: 入力連番 | K4: =J4=I4 -> TRUE
A5: 0008360479 | D5: 0008360479 | E5: =D5=A5 -> TRUE | I5: 検品倉庫コード | J5: 検品倉庫コード | K5: =J5=I5 -> TRUE
A6: 0008360488 | D6: 0008360488 | E6: =D6=A6 -> TRUE | I6: 取引先コード | J6: 取引先コード | K6: =J6=I6 -> TRUE
A7: 0008362536 | D7: 0008362536 | E7: =D7=A7 -> TRUE | I7: 納品形態区分 | J7: 納品形態区分 | K7: =J7=I7 -> TRUE
A8: 0008362545 | D8: 0008362545 | E8: =D8=A8 -> TRUE | I8: 便区分 | K8: =J8=I8 -> FALSE
A9: 0008362551 | D9: 0008362551 | E9: =D9=A9 -> TRUE | I9: 発注区分 | J9: 発注区分 | K9: =J9=I9 -> TRUE
A10: 0008362560 | D10: 0008362560 | E10: =D10=A10 -> TRUE | I10: 発注日 | J10: 発注日 | K10: =J10=I10 -> TRUE
A11: 0008362571 | D11: 0008362571 | E11: =D11=A11 -> TRUE | I11: 検品倉庫着荷指定日 | J11: 検品倉庫着荷指定日 | K11: =J11=I11 -> TRUE
A12: 0008364211 | D12: 0008364211 | E12: =D12=A12 -> TRUE | I12: 計上日 | J12: 計上日 | K12: =J12=I12 -> TRUE
A13: 0008364227 | D13: 0008364227 | E13: =D13=A13 -> TRUE | I13: 部門グループコード | J13: 部門グループコード | K13: =J13=I13 -> TRUE
A14: 0008364228 | D14: 0008364228 | E14: =D14=A14 -> TRUE | I14: 部門コード | J14: 部門コード | K14: =J14=I14 -> TRUE
A15: 0008364232 | D15: 0008364232 | E15: =D15=A15 -> TRUE | I15: 中分類コード | J15: 中分類コード | K15: =J15=I15 -> TRUE
A16: 0008365291 | D16: 0008365291 | E16: =D16=A16 -> TRUE | I16: 小分類コード | J16: 小分類コード | K16: =J16=I16 -> TRUE
A17: 0008365304 | D17: 0008365304 | E17: =D17=A17 -> TRUE | I17: 伝票番号 | J17: 伝票番号 | K17: =J17=I17 -> TRUE
A18: 0008365320 | D18: 0008365320 | E18: =D18=A18 -> TRUE | I18: 伝票行番号 | J18: 伝票行番号 | K18: =J18=I18 -> TRUE
A19: 0008389306 | D19: 0008389306 | E19: =D19=A19 -> TRUE | I19: 商品コード | J19: 商品コード | K19: =J19=I19 -> TRUE
A20: 0008389308 | D20: 0008389308 | E20: =D20=A20 -> TRUE | I20: 発注数量（バラ） | J20: 発注数量（バラ） | K20: =J20=I20 -> TRUE
A21: 0008400103 | D21: 0008400103 | E21: =D21=A21 -> TRUE | I21: 発注単位数 | J21: 発注単位数 | K21: =J21=I21 -> TRUE
A22: 0008408541 | D22: 0008408541 | E22: =D22=A22 -> TRUE | I22: 総重量 | K22: =J22=I22 -> FALSE
A23: 0008418212 | D23: 0008418212 | E23: =D23=A23 -> TRUE | I23: 確定数量（バラ） | J23: 確定数量（バラ） | K23: =J23=I23 -> TRUE
A24: 0008418217 | D24: 0008418217 | E24: =D24=A24 -> TRUE | I24: 欠品理由区分 | J24: 欠品理由区分 | K24: =J24=I24 -> TRUE
A25: 0008418218 | D25: 0008418218 | E25: =D25=A25 -> TRUE | I25: 欠品数量（バラ） | J25: 欠品数量（バラ） | K25: =J25=I25 -> TRUE
A26: 0008418220 | D26: 0008418220 | E26: =D26=A26 -> TRUE | I26: FILLER | J26: FILLER | K26: =J26=I26 -> TRUE
A27: 0008418237 | D27: 0008418237 | E27: =D27=A27 -> TRUE
A28: 0008418258 | D28: 0008418258 | E28: =D28=A28 -> TRUE
A29: 0008418272 | D29: 0008418272 | E29: =D29=A29 -> TRUE
A30: 0008418280 | D30: 0008418280 | E30: =D30=A30 -> TRUE
A31: 0008421253 | D31: 0008421253 | E31: =D31=A31 -> TRUE
A32: 0008421254 | D32: 0008421254 | E32: =D32=A32 -> TRUE
A33: 0008426855 | D33: 0008426855 | E33: =D33=A33 -> TRUE
A34: 0008461075 | D34: 0008461075 | E34: =D34=A34 -> TRUE
A35: 0008471649 | D35: 0008471649 | E35: =D35=A35 -> TRUE
A36: 0008473212 | D36: 0008473212 | E36: =D36=A36 -> TRUE
A37: 0008473214 | D37: 0008473214 | E37: =D37=A37 -> TRUE
A38: 0008482391 | D38: 0008482391 | E38: =D38=A38 -> TRUE
... A342: 0008528242 | D342: 0008528242 | E342: =D342=A342 -> TRUE
