Workbook

Sheet 見積書
F1: 見積№： | G1: （採番待ち）
F2: 作成日： | G2: 2026/10/07
A4: 御見積書
A6: (株)トライアルテクノロジー 御中 波多野 弘一 様 | E6: TRE-CHINA青島
E7: 中国・山東省青島市市北区龍城路39号
E8: 二十二世紀広電産業園10階
E9: TEL：86-532-85938100
E10: 李萌 | F10: 宮相聡 | G10: 臧鵬仕
A11: システム名 | B11: （採番待ち）
A12: プロジェクト名 | B12: （採番待ち）
A13: 発注枝番 | B13: （採番待ち）
A14: 発注内容 | B14: 生鮮IF増分（自動補充 生鮮IF）
A15: PJ形態 | B15: プロジェクト
A16: 見積金額 | B16: =TEXT(F37,"#,##0")&" 円（税抜き）"
A17: 支払条件 | B17: 検収月20日〆翌月払い
A18: 見積有効期限 | B18: 1ヶ月間
A21: No. | B21: タスク | C21: 単価 | D21: 工数(人日) | F21: 金額(円)
A22: 1 | B22: 調査・Mapping | C22: 40000 | D22: 39.5 | F22: =IF(D22="","",ROUND(C22*D22,0))
A23: 2 | B23: 詳細設計・開発・単体テスト | C23: 27500 | D23: 104 | F23: =IF(D23="","",ROUND(C23*D23,0))
A24: 3 | B24: プロジェクト管理 | C24: 40000 | D24: 14 | F24: =IF(D24="","",ROUND(C24*D24,0))
A25: 4 | B25: 基本設計
A26: 5 | B26: 概要設計
A27: 6 | B27: 結合テスト仕様書
A28: 7 | B28: 結合テスト
A29: 8 | B29: 総合テスト仕様書
A30: 9 | B30: 総合テスト
A31: 10 | B31: 操作マニュアル
A32: 11 | B32: 移行準備
A33: 12 | B33: 移行作業
A34: 13 | B34: 本番稼働立会い
B35: 小計 | D35: =SUM(D22:D34) | F35: =SUM(F22:F34)
B36: 契約形態 開発 消費税 0% | F36: 0
B37: 見積合計 | F37: =F35+F36
A39: 納品回数 | B39: 納品条件 | D39: 納品月 | E39: 検収月 | F39: 金額(税抜)
A40: 1回目 | B40: 生鮮IF増分 調査・Mapping完了 | D40: 202610 | E40: 202611 | F40: =F22
A41: 2回目 | B41: 生鮮IF増分 詳細設計・開発・単体テスト完了 | D41: 202612 | E41: 202701 | F41: =F23+F24
E42: 検収金額合計 | F42: =SUM(F40:F41)
A44: 備考 | B44: ・本見積の範囲は調査・Mapping〜詳細設計・開発・単体テストです。結合テスト以降、移行、本番稼働立会い、生鮮基幹／生鮮発注統合本体、@rms／EOS、倉庫系は含みません。
B45: ・店舗系12本の既存IFは、先方協議での流用方針を前提とします。当社は協議に未同席のため、流用可否の突合を本見積（流用確認・残件）に含みます。
B46: ・IF番号 S11〜S26 は仮採番です。前提（流用判定・生鮮データ作成時刻・連携先仕様）が変わる場合は、再見積のうえ調整します。
...

Sheet 作業タスク別見積
A1: ◆作業タスク別見積
A2: （採番待ち）:生鮮IF増分
A4: No. | B4: タスク | C4: 役割 | D4: 単価 | E4: 工数 | F4: 金額
A5: 1 | B5: 調査・Mapping | C5: SE | D5: =見積書!C22 | E5: =見積書!D22 | F5: =見積書!F22
A6: 2 | B6: 詳細設計・開発・単体テスト | C6: SE | D6: =見積書!C23 | E6: =見積書!D23 | F6: =見積書!F23
A7: 3 | B7: プロジェクト管理 | C7: SE | D7: =見積書!C24 | E7: =見積書!D24 | F7: =見積書!F24
A8: 4 | B8: 基本設計
A9: 5 | B9: 概要設計
A10: 6 | B10: 結合テスト仕様書
A11: 7 | B11: 結合テスト
A12: 8 | B12: 総合テスト仕様書
A13: 9 | B13: 総合テスト
A14: 10 | B14: 操作マニュアル
A15: 11 | B15: 移行準備
A16: 12 | B16: 移行作業
A17: 13 | B17: 本番稼働立会い
B18: 合計 | E18: =SUM(E5:E17) | F18: =SUM(F5:F17)

Sheet 機能別見積
A1: ◆機能別見積
A2: （採番待ち）:生鮮IF増分
A4: NO | B4: 機能 | C4: IF名称（仮採番） | D4: 区分 | E4: 新規/既存 | F4: 調査・Mapping | G4: 詳細設計 | H4: 開発 | I4: 単体テスト | J4: 内訳なし | K4: 合計
A5: 1 | B5: 生鮮発注勧告 | C5: 生鮮発注勧告(当日分)（S24） | D5: IF | E5: 新規 | F5: 5 | G5: 7.5 | H5: 7.5 | I5: 6.5 | J5: 0 | K5: =SUM(F5:J5)
A6: 2 | C6: 生鮮発注勧告(翌日以降分)（S25） | D6: IF | E6: 新規 | F6: 2.5 | G6: 3.5 | H6: 4 | I6: 3.5 | J6: 0 | K6: =SUM(F6:J6)
A7: 3 | C7: 生鮮勧告→発注統合変換（S26） | D7: IF | E7: 新規 | F7: 5 | G7: 6 | H7: 6 | I7: 5 | J7: 0 | K7: =SUM(F7:J7)
A8: 4 | B8: 生鮮入荷・発注 | C8: 生鮮入荷実績（S11） | D8: IF | E8: 差分 | F8: 4 | G8: 4.5 | H8: 6 | I8: 4 | J8: 0 | K8: =SUM(F8:J8)
A9: 5 | C9: 生鮮入荷予定（S12） | D9: IF | E9: 差分 | F9: 5 | G9: 5.5 | H9: 7.5 | I9: 4.5 | J9: 0 | K9: =SUM(F9:J9)
A10: 6 | C10: 生鮮発注スケジュール（S13） | D10: IF | E10: 差分 | F10: 5 | G10: 5.5 | H10: 7.5 | I10: 4.5 | J10: 0 | K10: =SUM(F10:J10)
A11: 7 | B11: 流用確認・残件 | C11: 店舗系12本の流用突合 | D11: 調査 | E11: 流用 | F11: 8 | G11: 0 | H11: 0 | I11: 0 | J11: 0 | K11: =SUM(F11:J11)
A12: 8 | C12: 倉庫系対象外の整理 | D12: 調査 | E12: 流用 | F12: 2 | G12: 0 | H12: 0 | I12: 0 | J12: 0 | K12: =SUM(F12:J12)
A13: 9 | C13: GCSアップロード要否の最終確認 | D13: 調査 | E13: 流用 | F13: 3 | G13: 0 | H13: 0 | I13: 0 | J13: 0 | K13: =SUM(F13:J13)
A14: 10 | B14: 非生鮮Phase2波及 | C14: 伝票区分・振替の注記反映 | D14: 改修 | E14: 既存 | F14: 0 | G14: 0 | H14: 0 | I14: 0 | J14: 5 | K14: =SUM(F14:J14)
C15: 小計 | F15: =SUM(F5:F14) | G15: =SUM(G5:G14) | H15: =SUM(H5:H14) | I15: =SUM(I5:I14) | J15: =SUM(J5:J14) | K15: =SUM(K5:K14)
C16: PJ管理 | K16: =見積書!D24
C17: 合計 | K17: =K15+K16

Sheet 工程計画
A1: ◆工程計画
A2: （採番待ち）:生鮮IF増分
A4: No. | B4: タスク | C4: 工数 | D4: 10月 | E4: 11月 | F4: 12月
A5: 1 | B5: 調査・Mapping | C5: =見積書!D22 | D5: 39.5
A6: 2 | B6: 詳細設計・開発・単体テスト | C6: =見積書!D23 | D6: 32.5 | E6: 64.5 | F6: 7
A7: 3 | B7: プロジェクト管理 | C7: =見積書!D24 | D7: 4 | E7: 7 | F7: 3
A8: 4 | B8: 基本設計
A9: 5 | B9: 概要設計
A10: 6 | B10: 結合テスト仕様書
A11: 7 | B11: 結合テスト
A12: 8 | B12: 総合テスト仕様書
A13: 9 | B13: 総合テスト
A14: 10 | B14: 操作マニュアル
A15: 11 | B15: 移行準備
A16: 12 | B16: 移行作業
A17: 13 | B17: 本番稼働立会い
B18: 合計 | C18: =SUM(C5:C17) | D18: =SUM(D5:D17) | E18: =SUM(E5:E17) | F18: =SUM(F5:F17)
A20: ※ 体制4名、2026/10/05着手、完了目安2026/12/08（概算）。月別は営業日按分の概算。
